# Test Suite Review

This document outlines the findings of a review of the project's test suite. It identifies failing tests, the root cause of the failures, and proposes solutions to fix them.

## `tests/test_chat_integration.py`

### Failing Test: `test_complete_chat_workflow`

*   **Reason for Failure:** The test asserts that all values in the embedding are of type `float`, but the embedding is a `numpy.ndarray` of `numpy.float32` values. The `isinstance()` check is too strict.
*   **Proposed Solution:** Modify the assertion to check for `np.floating` to correctly validate the data type of the embedding elements.

### Failing Test: `test_embedding_service_initialization`

*   **Reason for Failure:** The test asserts that the embedding is a `list`, but the `embed_text` function returns a `numpy.ndarray`.
*   **Proposed Solution:** Change the assertion to check if the embedding is an instance of `np.ndarray`.

## `tests/test_chat_service.py`

### Error: `ValueError: "AppConfig" object has no field "llm"`

*   **Reason for Failure:** The tests are attempting to assign an `LLMProviderConfig` object to a field named `llm` on the `AppConfig` instance. However, the `AppConfig` model in `config/models.py` defines this field as `llm_provider`, not `llm`.
*   **Proposed Solution:** Correct the test to use the proper field name, `llm_provider`, when assigning the `LLMProviderConfig` object.

## `tests/test_config.py`

### Failing Test: `test_create_production_config_with_env_vars`

*   **Reason for Failure:** The test correctly sets the `EMBEDDING_MODEL` environment variable, but the `create_production_config` function is not correctly reading this value. It appears to be loading the default value (`all-MiniLM-L6-v2`) instead of the value from the environment variable (`custom-model`).
*   **Proposed Solution:** Modify the `create_production_config` function in `config/factory.py` to ensure that it correctly reads the `EMBEDDING_MODEL` environment variable and applies it to the `EmbeddingConfig`.

## `tests/test_data_separation_fix.py`

### Warnings

*   **`PydanticDeprecatedSince20`**: This warning indicates that the `Field` function from Pydantic is being used with extra keyword arguments that are deprecated.
*   **`NotOpenSSLWarning`**: This is a warning from `urllib3` that the version of OpenSSL being used is not supported. This is a system-level issue and not something I can fix in the code.
*   **`RuntimeWarning: coroutine 'get_enhanced_day_data' was never awaited`**: This is a critical warning. It means that an `async` function is being called without `await`, so it's not actually running.
*   **`PytestReturnNotNoneWarning`**: This warning indicates that a test function is returning a value other than `None`. Test functions should use `assert` to check for conditions, not return values.

### Proposed Solutions

*   **`PydanticDeprecatedSince20`**: I will update the code to use `json_schema_extra` instead of the deprecated extra keyword arguments on the `Field` function.
*   **`RuntimeWarning`**: I will find the call to `get_enhanced_day_data` in the test and add the `await` keyword.
*   **`PytestReturnNotNoneWarning`**: I will remove the `return` statements from the test functions and use `assert` instead.

## `tests/test_embeddings.py`

### Failing Test: `test_cleanup`

*   **Reason for Failure:** The `cleanup` method in `EmbeddingService` is a synchronous function that tries to create an `asyncio` task. This fails because there is no running event loop in a synchronous test.
*   **Proposed Solution:** Convert the `test_cleanup` function to an `async` function and `await` the call to `embedding_service.cleanup()`.

### Failing Test: `test_embedding_error_handling`

*   **Reason for Failure:** The test asserts that the result of `embed_text` is an array of all zeros when an error occurs. However, the `embed_text` function returns a random array of floats in case of an error.
*   **Proposed Solution:** Modify the `embed_text` function to return an array of all zeros when an error occurs, as the test expects.

## `tests/test_integration.py`

### Failing Test: `test_service_initialization`

*   **Reason for Failure:** The test asserts that the `ingestion_service` has a `processor` attribute, but it is no longer an attribute of the `IngestionService` class.
*   **Proposed Solution:** Remove the assertion that checks for the `processor` attribute.

### Failing Test: `test_manual_item_ingestion`

*   **Reason for Failure:** The test asserts that the `metadata` of the ingested item contains a `processing_history` key. However, the `manual_ingest_item` function does not add this key to the metadata.
*   **Proposed Solution:** Modify the `manual_ingest_item` function to add the `processing_history` key to the metadata of the ingested item.

### Failing Test: `test_incremental_sync_behavior`

*   **Reason for Failure:** The test is mocking the `sources.sync_manager.SyncManager.sync_source` method, but the `ingest_from_source` method in `IngestionService` calls `sync_manager.sync` instead.
*   **Proposed Solution:** Update the test to patch `sources.sync_manager.SyncManager.sync` instead of `sources.sync_manager.SyncManager.sync_source`.

## `tests/test_limitless_processor.py`

### Failing Test: `test_empty_content_hash`

*   **Reason for Failure:** The test asserts that the `content_hash` in the deduplication metadata is not `None` for an item with empty content. However, the `DeduplicationProcessor` does not generate a hash for empty content, resulting in a `None` value.
*   **Proposed Solution:** Modify the `DeduplicationProcessor` to generate a hash for empty content, which will ensure that the `content_hash` is never `None`.

## `tests/test_limitless_source.py`

### Failing Tests: `test_test_connection_success` and `test_test_connection_failure`

*   **Reason for Failure:** The `test_connection` method in `LimitlessSource` is not returning a boolean value as expected. It appears to be returning `None`.
*   **Proposed Solution:** Modify the `test_connection` method in `sources/limitless.py` to return `True` on success and `False` on failure.

### Failing Test: `test_retry_logic_on_rate_limit`

*   **Reason for Failure:** The test is asserting that one item is fetched after a rate limit error, but it appears that no items are being fetched. This is likely due to an issue with the retry logic in the `fetch_items` method.
*   **Proposed Solution:** Examine the `fetch_items` method in `sources/limitless.py` and correct the retry logic to ensure that it correctly handles rate limit errors and retries the request.

## `tests/test_llm_base.py`

### Failing Test: `test_provider_parameter_validation_in_context`

*   **Reason for Failure:** The test expects a `ValueError` to be raised when `generate_response` is called with a negative `max_tokens` value. However, the `generate_response` method in the `MockLLMProvider` does not perform any validation on the input parameters.
*   **Proposed Solution:** Add validation to the `generate_response` method in the `MockLLMProvider` to raise a `ValueError` if `max_tokens` is not a positive integer.

## `tests/test_llm_factory.py`

### Failing Test: `test_factory_with_invalid_config`

*   **Reason for Failure:** The test is attempting to create an `LLMProviderConfig` with an invalid provider name, which correctly raises a `ValidationError`. However, the test is not expecting this exception and is therefore failing.
*   **Proposed Solution:** Wrap the instantiation of `LLMProviderConfig` in a `pytest.raises` block to assert that a `ValidationError` is raised.

## `tests/test_llm_integration.py`

### Failing Test: `test_check_all_providers`

*   **Reason for Failure:** The test is attempting to call `check_all_providers` on an `async_generator` object, which does not have this method. This is because the `multi_factory` fixture is an `async_generator` and not an instance of `LLMProviderFactory`.
*   **Proposed Solution:** Modify the test to correctly call `check_all_providers` on the `LLMProviderFactory` instance.

### Failing Tests: `test_ollama_not_available` and `test_openai_invalid_key`

*   **Reason for Failure:** Both of these tests are failing because the `is_available` method in the `OllamaProvider` and `OpenAIProvider` classes is calling `super().test_connection()`, but the `BaseLLMProvider` class does not have a `test_connection` method.
*   **Proposed Solution:** Modify the `OllamaProvider` and `OpenAIProvider` classes to correctly call the `test_connection` method from the `HTTPClientMixin`.
